<?xml version="1.0" ?>
<sdf version="1.9">
  <model name="three_wheel_bot">
    <pose>0 0 0.05 0 0 0</pose>
    <static>false</static>

    <!-- Base -->
    <link name="base_link">
      <pose>0 0 0.05 0 0 0</pose>
      <inertial>
        <mass>6.0</mass>
        <inertia>
          <ixx>0.12</ixx><iyy>0.12</iyy><izz>0.2</izz>
        </inertia>
      </inertial>
      <collision name="base_collision">
        <geometry><box><size>0.35 0.25 0.1</size></box></geometry>
      </collision>
      <visual name="base_visual">
        <geometry><box><size>0.35 0.25 0.1</size></box></geometry>
      </visual>
    </link>

    <!-- Wheels -->
    <link name="left_wheel">
      <pose>0 -0.13 0.05 0 0 0</pose>
      <inertial><mass>0.6</mass><inertia><ixx>0.002</ixx><iyy>0.004</iyy><izz>0.004</izz></inertia></inertial>
      <collision name="left_wheel_collision"><geometry><cylinder><radius>0.05</radius><length>0.03</length></cylinder></geometry></collision>
      <visual name="left_wheel_visual"><geometry><cylinder><radius>0.05</radius><length>0.03</length></cylinder></geometry></visual>
    </link>

    <link name="right_wheel">
      <pose>0 0.13 0.05 0 0 0</pose>
      <inertial><mass>0.6</mass><inertia><ixx>0.002</ixx><iyy>0.004</iyy><izz>0.004</izz></inertia></inertial>
      <collision name="right_wheel_collision"><geometry><cylinder><radius>0.05</radius><length>0.03</length></cylinder></geometry></collision>
      <visual name="right_wheel_visual"><geometry><cylinder><radius>0.05</radius><length>0.03</length></cylinder></geometry></visual>
    </link>

    <!-- Front caster -->
    <link name="front_caster">
      <pose>0.15 0 0.03 0 0 0</pose>
      <inertial><mass>0.3</mass><inertia><ixx>0.001</ixx><iyy>0.001</iyy><izz>0.001</izz></inertia></inertial>
      <collision name="caster_collision"><geometry><sphere><radius>0.03</radius></sphere></geometry></collision>
      <visual name="caster_visual"><geometry><sphere><radius>0.03</radius></sphere></geometry></visual>
    </link>

    <!-- Joints -->
    <joint name="left_wheel_joint" type="revolute">
      <parent>base_link</parent><child>left_wheel</child>
      <axis><xyz>0 1 0</xyz><dynamics><damping>0.01</damping></dynamics></axis>
    </joint>

    <joint name="right_wheel_joint" type="revolute">
      <parent>base_link</parent><child>right_wheel</child>
      <axis><xyz>0 1 0</xyz><dynamics><damping>0.01</damping></dynamics></axis>
    </joint>

    <joint name="caster_joint" type="revolute">
      <parent>base_link</parent><child>front_caster</child>
      <axis><xyz>0 0 1</xyz><dynamics><damping>0.05</damping></dynamics></axis>
    </joint>

    <!-- Sensor mount -->
    <link name="sensor_mount">
      <pose>0.12 0 0.14 0 0 0</pose>
      <inertial><mass>0.2</mass><inertia><ixx>0.0005</ixx><iyy>0.0005</iyy><izz>0.0005</izz></inertia></inertial>

      <!-- IMU -->
      <sensor name="imu" type="imu">
        <update_rate>200</update_rate>
        <always_on>true</always_on>
        <plugin name="imu_plugin" filename="gz-sensors-imu-system"><topic>/imu/data</topic></plugin>
      </sensor>

      <!-- RGB camera -->
      <sensor name="camera" type="camera">
        <update_rate>30</update_rate>
        <camera><horizontal_fov>1.047</horizontal_fov><image><width>640</width><height>480</height><format>R8G8B8</format></image><clip><near>0.05</near><far>50</far></clip></camera>
        <plugin name="camera_plugin" filename="gz-sensors-camera-system"><topic>/camera/image_raw</topic></plugin>
      </sensor>

      <!-- Planar LiDAR (proximity) -->
      <sensor name="lidar" type="gpu_lidar">
        <update_rate>20</update_rate>
        <ray>
          <scan><horizontal><samples>360</samples><min_angle>-1.57</min_angle><max_angle>1.57</max_angle></horizontal></scan>
          <range><min>0.02</min><max>12.0</max></range>
        </ray>
        <plugin name="lidar_plugin" filename="gz-sensors-gpu-lidar-system"><topic>/scan</topic></plugin>
      </sensor>
    </link>

    <joint name="sensor_mount_joint" type="fixed"><parent>base_link</parent><child>sensor_mount</child></joint>

    <!-- Differential drive plugin (Ignition/Gazebo garden style) -->
    <plugin name="diff_drive" filename="gz-sim-diff-drive-system">
      <left_joint>left_wheel_joint</left_joint>
      <right_joint>right_wheel_joint</right_joint>
      <wheel_separation>0.26</wheel_separation>
      <wheel_radius>0.05</wheel_radius>
      <cmd_vel_topic>/cmd_vel</cmd_vel_topic>
      <odom_topic>/odom</odom_topic>
      <odom_publish_frequency>50</odom_publish_frequency>
      <robot_base_frame>base_link</robot_base_frame>
    </plugin>

  </model>
</sdf>
